Workbook

Sheet 📊 Dashboard
A1: 🛒 SuperMart Retail Chain — Sales Performance Dashboard | FY 2024
A2: 500 Transactions · 5 Regions · 5 Categories · 10 Salespersons · Jan – Dec 2024
A4: 💰 TOTAL REVENUE | E4: 📦 TOTAL ORDERS | I4: 📈 AVG MARGIN | M4: 🏆 TOP REGION | Q4: ⚠️ RETURN RATE
A5: =SUM(Sales_Data!L:L) -> 88178490 | E5: =COUNTA(Sales_Data!A2:A501) -> 500 | I5: =AVERAGE(Sales_Data!O2:O501) -> 0.3007364 | M5: =INDEX(Regional_Analysis!A3:A7,MATCH(MAX(Regional_Analysis!D3:D7),Regional_Analysis!D3:D7,0)) -> South | Q5: =IFERROR(COUNTIF(Sales_Data!P:P,"Yes")/COUNTA(Sales_Data!A2:A501),0) -> 0.04
A6: ="vs Target: ₹" & TEXT(SUM(Sales_Data!L:L)/50000000*100,"0.0") & "% of ₹5Cr Goal" -> vs Target: ₹176.4% of ₹5Cr Goal | E6: =COUNTA(Sales_Data!A2:A501) & " transactions processed" -> 500 transactions processed | I6: "Target: 30.0% | Blended across all categories" | M6: =INDEX(Regional_Analysis!A3:A7,MATCH(MAX(Regional_Analysis!D3:D7),Regional_Analysis!D3:D7,0))&" leads with ₹"&TEXT(MAX(Regional_Analysis!D3:D7),"#,##0") -> South leads with ₹20,329,410 | Q6: =COUNTIF(Sales_Data!P:P,"Yes")&" returns out of 500 orders" -> 20 returns out of 500 orders
A10: 📅 Monthly Revenue Trend
A11: Jan | B11: Feb | C11: Mar | D11: Apr | E11: May | F11: Jun | G11: Jul | H11: Aug | I11: Sep | J11: Oct | K11: Nov | L11: Dec
A12: =SUMIF(Sales_Data!C:C,"January",Sales_Data!L:L) -> 6580400 | B12: =SUMIF(Sales_Data!C:C,"February",Sales_Data!L:L) -> 8919190 | C12: =SUMIF(Sales_Data!C:C,"March",Sales_Data!L:L) -> 5759980 | D12: =SUMIF(Sales_Data!C:C,"April",Sales_Data!L:L) -> 5818470 | E12: =SUMIF(Sales_Data!C:C,"May",Sales_Data!L:L) -> 9601970 | F12: =SUMIF(Sales_Data!C:C,"June",Sales_Data!L:L) -> 6869620 | G12: =SUMIF(Sales_Data!C:C,"July",Sales_Data!L:L) -> 6966520 | H12: =SUMIF(Sales_Data!C:C,"August",Sales_Data!L:L) -> 8013470 | I12: =SUMIF(Sales_Data!C:C,"September",Sales_Data!L:L) -> 5430530 | J12: =SUMIF(Sales_Data!C:C,"October",Sales_Data!L:L) -> 8198170 | K12: =SUMIF(Sales_Data!C:C,"November",Sales_Data!L:L) -> 10027570 | L12: =SUMIF(Sales_Data!C:C,"December",Sales_Data!L:L) -> 5992600
A14: 🗺️ Regional Breakdown
A15: Region | B15: Revenue (₹) | C15: Orders | D15: Margin % | E15: Share % | F15: Rank | G15: Returns
A16: North | B16: =SUMIF(Sales_Data!E:E,A16,Sales_Data!L:L) -> 16101730 | C16: =COUNTIF(Sales_Data!E:E,A16) -> 94 | D16: =IFERROR(SUMIF(Sales_Data!E:E,A16,Sales_Data!N:N)/SUMIF(Sales_Data!E:E,A16,Sales_Data!L:L),0) -> 0.28347222 | E16: =IFERROR(B16/SUM($B$16:$B$20),0) -> 0.18260383 | F16: =RANK(B16,$B$16:$B$20,0) -> 4 | G16: =COUNTIFS(Sales_Data!E:E,A16,Sales_Data!P:P,"Yes") -> 5
A17: South | B17: =SUMIF(Sales_Data!E:E,A17,Sales_Data!L:L) -> 20329410 | C17: =COUNTIF(Sales_Data!E:E,A17) -> 114 | D17: =IFERROR(SUMIF(Sales_Data!E:E,A17,Sales_Data!N:N)/SUMIF(Sales_Data!E:E,A17,Sales_Data!L:L),0) -> 0.26271959 | E17: =IFERROR(B17/SUM($B$16:$B$20),0) -> 0.2305484 | F17: =RANK(B17,$B$16:$B$20,0) -> 1 | G17: =COUNTIFS(Sales_Data!E:E,A17,Sales_Data!P:P,"Yes") -> 7
A18: East | B18: =SUMIF(Sales_Data!E:E,A18,Sales_Data!L:L) -> 18011490 | C18: =COUNTIF(Sales_Data!E:E,A18) -> 92 | D18: =IFERROR(SUMIF(Sales_Data!E:E,A18,Sales_Data!N:N)/SUMIF(Sales_Data!E:E,A18,Sales_Data!L:L),0) -> 0.27351341 | E18: =IFERROR(B18/SUM($B$16:$B$20),0) -> 0.20426172 | F18: =RANK(B18,$B$16:$B$20,0) -> 3 | G18: =COUNTIFS(Sales_Data!E:E,A18,Sales_Data!P:P,"Yes") -> 3
A19: West | B19: =SUMIF(Sales_Data!E:E,A19,Sales_Data!L:L) -> 13755920 | C19: =COUNTIF(Sales_Data!E:E,A19) -> 89 | D19: =IFERROR(SUMIF(Sales_Data!E:E,A19,Sales_Data!N:N)/SUMIF(Sales_Data!E:E,A19,Sales_Data!L:L),0) -> 0.29392997 | E19: =IFERROR(B19/SUM($B$16:$B$20),0) -> 0.15600086 | F19: =RANK(B19,$B$16:$B$20,0) -> 5 | G19: =COUNTIFS(Sales_Data!E:E,A19,Sales_Data!P:P,"Yes") -> 2
A20: Central | B20: =SUMIF(Sales_Data!E:E,A20,Sales_Data!L:L) -> 19979940 | C20: =COUNTIF(Sales_Data!E:E,A20) -> 111 | D20: =IFERROR(SUMIF(Sales_Data!E:E,A20,Sales_Data!N:N)/SUMIF(Sales_Data!E:E,A20,Sales_Data!L:L),0) -> 0.27947021 | E20: =IFERROR(B20/SUM($B$16:$B$20),0) -> 0.22658519 | F20: =RANK(B20,$B$16:$B$20,0) -> 2 | G20: =COUNTIFS(Sales_Data!E:E,A20,Sales_Data!P:P,"Yes") -> 3
A22: 🏷️ Category Performance
A23: Category | B23: Revenue (₹) | C23: Units | D23: Margin % | E23: Orders | F23: Return Rate
A24: Electronics | B24: =SUMIF(Sales_Data!G:G,A24,Sales_Data!L:L) -> 46970140 | C24: =SUMIF(Sales_Data!G:G,A24,Sales_Data!J:J) -> 1033 | D24: =IFERROR(SUMIF(Sales_Data!G:G,A24,Sales_Data!N:N)/SUMIF(Sales_Data!G:G,A24,Sales_Data!L:L),0) -> 0.22342615 | E24: =COUNTIF(Sales_Data!G:G,A24) -> 91 | F24: =IFERROR(COUNTIFS(Sales_Data!G:G,A24,Sales_Data!P:P,"Yes")/COUNTIF(Sales_Data!G:G,A24),0) -> 0.065934066
A25: Clothing | B25: =SUMIF(Sales_Data!G:G,A25,Sales_Data!L:L) -> 2941370 | C25: =SUMIF(Sales_Data!G:G,A25,Sales_Data!J:J) -> 969 | D25: =IFERROR(SUMIF(Sales_Data!G:G,A25,Sales_Data!N:N)/SUMIF(Sales_Data!G:G,A25,Sales_Data!L:L),0) -> 0.44848073 | E25: =COUNTIF(Sales_Data!G:G,A25) -> 86 | F25: =IFERROR(COUNTIFS(Sales_Data!G:G,A25,Sales_Data!P:P,"Yes")/COUNTIF(Sales_Data!G:G,A25),0) -> 0.023255814
A26: Groceries | B26: =SUMIF(Sales_Data!G:G,A26,Sales_Data!L:L) -> 1224330 | C26: =SUMIF(Sales_Data!G:G,A26,Sales_Data!J:J) -> 1050 | D26: =IFERROR(SUMIF(Sales_Data!G:G,A26,Sales_Data!N:N)/SUMIF(Sales_Data!G:G,A26,Sales_Data!L:L),0) -> 0.18633069 | E26: =COUNTIF(Sales_Data!G:G,A26) -> 97 | F26: =IFERROR(COUNTIFS(Sales_Data!G:G,A26,Sales_Data!P:P,"Yes")/COUNTIF(Sales_Data!G:G,A26),0) -> 0.041237113
A27: Furniture | B27: =SUMIF(Sales_Data!G:G,A27,Sales_Data!L:L) -> 28889360 | C27: =SUMIF(Sales_Data!G:G,A27,Sales_Data!J:J) -> 1218 | D27: =IFERROR(SUMIF(Sales_Data!G:G,A27,Sales_Data!N:N)/SUMIF(Sales_Data!G:G,A27,Sales_Data!L:L),0) -> 0.34628232 | E27: =COUNTIF(Sales_Data!G:G,A27) -> 119 | F27: =IFERROR(COUNTIFS(Sales_Data!G:G,A27,Sales_Data!P:P,"Yes")/COUNTIF(Sales_Data!G:G,A27),0) -> 0.042016807
A28: Sports | B28: =SUMIF(Sales_Data!G:G,A28,Sales_Data!L:L) -> 8153290 | C28: =SUMIF(Sales_Data!G:G,A28,Sales_Data!J:J) -> 1084 | D28: =IFERROR(SUMIF(Sales_Data!G:G,A28,Sales_Data!N:N)/SUMIF(Sales_Data!G:G,A28,Sales_Data!L:L),0) -> 0.29598805 | E28: =COUNTIF(Sales_Data!G:G,A28) -> 107 | F28: =IFERROR(COUNTIFS(Sales_Data!G:G,A28,Sales_Data!P:P,"Yes")/COUNTIF(Sales_Data!G:G,A28),0) -> 0.028037383
A30: 🏆 Top Salesperson Leaderboard
A31: Rank | B31: Salesperson | C31: Region | D31: Revenue (₹) | E31: Margin % | F31: Rating
A32: 🥇 | B32: =INDEX(Salesperson_Scorecard!$A$4:$A$13,MATCH(LARGE(Salesperson_Scorecard!$E$4:$E$13,1),Salesperson_Scorecard!$E$4:$E$13,0)) -> Rahul Gupta | C32: =INDEX(Salesperson_Scorecard!$B$4:$B$13,MATCH(LARGE(Salesperson_Scorecard!$E$4:$E$13,1),Salesperson_Scorecard!$E$4:$E$13,0)) -> South | D32: =LARGE(Salesperson_Scorecard!$E$4:$E$13,1) -> 13650710 | E32: =INDEX(Salesperson_Scorecard!$G$4:$G$13,MATCH(LARGE(Salesperson_Scorecard!$E$4:$E$13,1),Salesperson_Scorecard!$E$4:$E$13,0)) -> 0.2492927 | F32: =INDEX(Salesperson_Scorecard!$J$4:$J$13,MATCH(LARGE(Salesperson_Scorecard!$E$4:$E$13,1),Salesperson_Scorecard!$E$4:$E$13,0)) -> ⭐ Excellent
A33: 🥈 | B33: =INDEX(Salesperson_Scorecard!$A$4:$A$13,MATCH(LARGE(Salesperson_Scorecard!$E$4:$E$13,2),Salesperson_Scorecard!$E$4:$E$13,0)) -> Suresh Kumar | C33: =INDEX(Salesperson_Scorecard!$B$4:$B$13,MATCH(LARGE(Salesperson_Scorecard!$E$4:$E$13,2),Salesperson_Scorecard!$E$4:$E$13,0)) -> Central | D33: =LARGE(Salesperson_Scorecard!$E$4:$E$13,2) -> 11511390 | E33: =INDEX(Salesperson_Scorecard!$G$4:$G$13,MATCH(LARGE(Salesperson_Scorecard!$E$4:$E$13,2),Salesperson_Scorecard!$E$4:$E$13,0)) -> 0.28254722 | F33: =INDEX(Salesperson_Scorecard!$J$4:$J$13,MATCH(LARGE(Salesperson_Scorecard!$E$4:$E$13,2),Salesperson_Scorecard!$E$4:$E$13,0)) -> ⭐ Excellent
A34: 🥉 | B34: =INDEX(Salesperson_Scorecard!$A$4:$A$13,MATCH(LARGE(Salesperson_Scorecard!$E$4:$E$13,3),Salesperson_Scorecard!$E$4:$E$13,0)) -> Amit Singh | C34: =INDEX(Salesperson_Scorecard!$B$4:$B$13,MATCH(LARGE(Salesperson_Scorecard!$E$4:$E$13,3),Salesperson_Scorecard!$E$4:$E$13,0)) -> East | D34: =LARGE(Salesperson_Scorecard!$E$4:$E$13,3) -> 9674340 | E34: =INDEX(Salesperson_Scorecard!$G$4:$G$13,MATCH(LARGE(Salesperson_Scorecard!$E$4:$E$13,3),Salesperson_Scorecard!$E$4:$E$13,0)) -> 0.27407564 | F34: =INDEX(Salesperson_Scorecard!$J$4:$J$13,MATCH(LARGE(Salesperson_Scorecard!$E$4:$E$13,3),Salesperson_Scorecard!$E$4:$E$13,0)) -> ⭐ Excellent
A35: 4 | B35: =INDEX(Salesperson_Scorecard!$A$4:$A$13,MATCH(LARGE(Salesperson_Scorecard!$E$4:$E$13,4),Salesperson_Scorecard!$E$4:$E$13,0)) -> Arjun Sharma | C35: =INDEX(Salesperson_Scorecard!$B$4:$B$13,MATCH(LARGE(Salesperson_Scorecard!$E$4:$E$13,4),Salesperson_Scorecard!$E$4:$E$13,0)) -> North | D35: =LARGE(Salesperson_Scorecard!$E$4:$E$13,4) -> 8979690 | E35: =INDEX(Salesperson_Scorecard!$G$4:$G$13,MATCH(LARGE(Salesperson_Scorecard!$E$4:$E$13,4),Salesperson_Scorecard!$E$4:$E$13,0)) -> 0.27551819 | F35: =INDEX(Salesperson_Scorecard!$J$4:$J$13,MATCH(LARGE(Salesperson_Scorecard!$E$4:$E$13,4),Salesperson_Scorecard!$E$4:$E$13,0)) -> ⭐ Excellent
A36: 5 | B36: =INDEX(Salesperson_Scorecard!$A$4:$A$13,MATCH(LARGE(Salesperson_Scorecard!$E$4:$E$13,5),Salesperson_Scorecard!$E$4:$E$13,0)) -> Meera Joshi | C36: =INDEX(Salesperson_Scorecard!$B$4:$B$13,MATCH(LARGE(Salesperson_Scorecard!$E$4:$E$13,5),Salesperson_Scorecard!$E$4:$E$13,0)) -> Central | D36: =LARGE(Salesperson_Scorecard!$E$4:$E$13,5) -> 8468550 | E36: =INDEX(Salesperson_Scorecard!$G$4:$G$13,MATCH(LARGE(Salesperson_Scorecard!$E$4:$E$13,5),Salesperson_Scorecard!$E$4:$E$13,0)) -> 0.27528761 | F36: =INDEX(Salesperson_Scorecard!$J$4:$J$13,MATCH(LARGE(Salesperson_Scorecard!$E$4:$E$13,5),Salesperson_Scorecard!$E$4:$E$13,0)) -> ⭐ Excellent
A37: 6 | B37: =INDEX(Salesperson_Scorecard!$A$4:$A$13,MATCH(LARGE(Salesperson_Scorecard!$E$4:$E$13,6),Salesperson_Scorecard!$E$4:$E$13,0)) -> Kavya Nair | C37: =INDEX(Salesperson_Scorecard!$B$4:$B$13,MATCH(LARGE(Salesperson_Scorecard!$E$4:$E$13,6),Salesperson_Scorecard!$E$4:$E$13,0)) -> East | D37: =LARGE(Salesperson_Scorecard!$E$4:$E$13,6) -> 8337150 | E37: =INDEX(Salesperson_Scorecard!$G$4:$G$13,MATCH(LARGE(Salesperson_Scorecard!$E$4:$E$13,6),Salesperson_Scorecard!$E$4:$E$13,0)) -> 0.27286102 | F37: =INDEX(Salesperson_Scorecard!$J$4:$J$13,MATCH(LARGE(Salesperson_Scorecard!$E$4:$E$13,6),Salesperson_Scorecard!$E$4:$E$13,0)) -> ⭐ Excellent
A38: 7 | B38: =INDEX(Salesperson_Scorecard!$A$4:$A$13,MATCH(LARGE(Salesperson_Scorecard!$E$4:$E$13,7),Salesperson_Scorecard!$E$4:$E$13,0)) -> Priya Patel | C38: =INDEX(Salesperson_Scorecard!$B$4:$B$13,MATCH(LARGE(Salesperson_Scorecard!$E$4:$E$13,7),Salesperson_Scorecard!$E$4:$E$13,0)) -> North | D38: =LARGE(Salesperson_Scorecard!$E$4:$E$13,7) -> 7122040 | E38: =INDEX(Salesperson_Scorecard!$G$4:$G$13,MATCH(LARGE(Salesperson_Scorecard!$E$4:$E$13,7),Salesperson_Scorecard!$E$4:$E$13,0)) -> 0.29350091 | F38: =INDEX(Salesperson_Scorecard!$J$4:$J$13,MATCH(LARGE(Salesperson_Scorecard!$E$4:$E$13,7),Salesperson_Scorecard!$E$4:$E$13,0)) -> ⭐ Excellent
A39: 8 | B39: =INDEX(Salesperson_Scorecard!$A$4:$A$13,MATCH(LARGE(Salesperson_Scorecard!$E$4:$E$13,8),Salesperson_Scorecard!$E$4:$E$13,0)) -> Rohan Mehta | C39: =INDEX(Salesperson_Scorecard!$B$4:$B$13,MATCH(LARGE(Salesperson_Scorecard!$E$4:$E$13,8),Salesperson_Scorecard!$E$4:$E$13,0)) -> West | D39: =LARGE(Salesperson_Scorecard!$E$4:$E$13,8) -> 6920960 | E39: =INDEX(Salesperson_Scorecard!$G$4:$G$13,MATCH(LARGE(Salesperson_Scorecard!$E$4:$E$13,8),Salesperson_Scorecard!$E$4:$E$13,0)) -> 0.27634747 | F39: =INDEX(Salesperson_Scorecard!$J$4:$J$13,MATCH(LARGE(Salesperson_Scorecard!$E$4:$E$13,8),Salesperson_Scorecard!$E$4:$E$13,0)) -> ⭐ Excellent
A40: 9 | B40: =INDEX(Salesperson_Scorecard!$A$4:$A$13,MATCH(LARGE(Salesperson_Scorecard!$E$4:$E$13,9),Salesperson_Scorecard!$E$4:$E$13,0)) -> Divya Iyer | C40: =INDEX(Salesperson_Scorecard!$B$4:$B$13,MATCH(LARGE(Salesperson_Scorecard!$E$4:$E$13,9),Salesperson_Scorecard!$E$4:$E$13,0)) -> West | D40: =LARGE(Salesperson_Scorecard!$E$4:$E$13,9) -> 6834960 | E40: =INDEX(Salesperson_Scorecard!$G$4:$G$13,MATCH(LARGE(Salesperson_Scorecard!$E$4:$E$13,9),Salesperson_Scorecard!$E$4:$E$13,0)) -> 0.31173369 | F40: =INDEX(Salesperson_Scorecard!$J$4:$J$13,MATCH(LARGE(Salesperson_Scorecard!$E$4:$E$13,9),Salesperson_Scorecard!$E$4:$E$13,0)) -> ⭐ Excellent
A41: 10 | B41: =INDEX(Salesperson_Scorecard!$A$4:$A$13,MATCH(LARGE(Salesperson_Scorecard!$E$4:$E$13,10),Salesperson_Scorecard!$E$4:$E$13,0)) -> Sneha Reddy | C41: =INDEX(Salesperson_Scorecard!$B$4:$B$13,MATCH(LARGE(Salesperson_Scorecard!$E$4:$E$13,10),Salesperson_Scorecard!$E$4:$E$13,0)) -> South | D41: =LARGE(Salesperson_Scorecard!$E$4:$E$13,10) -> 6678700 | E41: =INDEX(Salesperson_Scorecard!$G$4:$G$13,MATCH(LARGE(Salesperson_Scorecard!$E$4:$E$13,10),Salesperson_Scorecard!$E$4:$E$13,0)) -> 0.29016303 | F41: =INDEX(Salesperson_Scorecard!$J$4:$J$13,MATCH(LARGE(Salesperson_Scorecard!$E$4:$E$13,10),Salesperson_Scorecard!$E$4:$E$13,0)) -> ⭐ Excellent
A43: 📊 Quarterly Performance Summary
A44: Quarter | B44: Revenue (₹) | C44: Orders | D44: Gross Profit (₹) | E44: Margin % | F44: Units | G44: Returns | H44: QoQ Growth %
A45: Q1 | B45: =SUMIF(Sales_Data!D:D,A45,Sales_Data!L:L) -> 21259570 | C45: =COUNTIF(Sales_Data!D:D,A45) -> 124 | D45: =SUMIF(Sales_Data!D:D,A45,Sales_Data!N:N) -> 6053272.9 | E45: =IFERROR(D45/B45,0) -> 0.28473167 | F45: =SUMIF(Sales_Data!D:D,A45,Sales_Data!J:J) -> 1397 | G45: =COUNTIFS(Sales_Data!D:D,A45,Sales_Data!P:P,"Yes") -> 9 | H45: —
A46: Q2 | B46: =SUMIF(Sales_Data!D:D,A46,Sales_Data!L:L) -> 22290060 | C46: =COUNTIF(Sales_Data!D:D,A46) -> 118 | D46: =SUMIF(Sales_Data!D:D,A46,Sales_Data!N:N) -> 6042223.2 | E46: =IFERROR(D46/B46,0) -> 0.27107254 | F46: =SUMIF(Sales_Data!D:D,A46,Sales_Data!J:J) -> 1246 | G46: =COUNTIFS(Sales_Data!D:D,A46,Sales_Data!P:P,"Yes") -> 4 | H46: =IFERROR((B46-B45)/B45,0) -> 0.048471818
A47: Q3 | B47: =SUMIF(Sales_Data!D:D,A47,Sales_Data!L:L) -> 20410520 | C47: =COUNTIF(Sales_Data!D:D,A47) -> 109 | D47: =SUMIF(Sales_Data!D:D,A47,Sales_Data!N:N) -> 5450371.2 | E47: =IFERROR(D47/B47,0) -> 0.26703735 | F47: =SUMIF(Sales_Data!D:D,A47,Sales_Data!J:J) -> 1132 | G47: =COUNTIFS(Sales_Data!D:D,A47,Sales_Data!P:P,"Yes") -> 2 | H47: =IFERROR((B47-B46)/B46,0) -> -0.084321891
A48: Q4 | B48: =SUMIF(Sales_Data!D:D,A48,Sales_Data!L:L) -> 24218340 | C48: =COUNTIF(Sales_Data!D:D,A48) -> 149 | D48: =SUMIF(Sales_Data!D:D,A48,Sales_Data!N:N) -> 6912919.4 | E48: =IFERROR(D48/B48,0) -> 0.2854415 | F48: =SUMIF(Sales_Data!D:D,A48,Sales_Data!J:J) -> 1579 | G48: =COUNTIFS(Sales_Data!D:D,A48,Sales_Data!P:P,"Yes") -> 5 | H48: =IFERROR((B48-B47)/B47,0) -> 0.18656164
...

Sheet Sales_Data
A1: Order_ID | B1: Order_Date | C1: Month | D1: Quarter | E1: Region | F1: Store | G1: Category | H1: Product | I1: Salesperson | J1: Units | K1: Unit_Price | L1: Revenue | M1: COGS | N1: Gross_Profit | O1: Profit_Margin% | P1: Return_Flag
A2: ORD-1001 | B2: 45619 | C2: November | D2: Q4 | E2: North | F2: Delhi-01 | G2: Groceries | H2: Cooking Oil 5L | I2: Arjun Sharma | J2: 4 | K2: 450 | L2: 1800 | M2: 1444.19 | N2: 355.81 | O2: 0.1977 | P2: No
A3: ORD-1002 | B3: 45336 | C3: February | D3: Q1 | E3: Central | F3: Bhopal-01 | G3: Electronics | H3: Samsung TV 55" | I3: Suresh Kumar | J3: 17 | K3: 21400 | L3: 363800 | M3: 280052.56 | N3: 83747.44 | O3: 0.2302 | P3: No
A4: ORD-1003 | B4: 45624 | C4: November | D4: Q4 | E4: Central | F4: Bhopal-01 | G4: Clothing | H4: Formal Suit | I4: Meera Joshi | J4: 1 | K4: 1750 | L4: 1750 | M4: 917.21 | N4: 832.79 | O4: 0.4759 | P4: No
A5: ORD-1004 | B5: 45508 | C5: August | D5: Q3 | E5: East | F5: Bhubaneswar-01 | G5: Clothing | H5: Denim Jeans | I5: Amit Singh | J5: 13 | K5: 960 | L5: 12480 | M5: 7367.3 | N5: 5112.7 | O5: 0.4097 | P5: No
A6: ORD-1005 | B6: 45601 | C6: November | D6: Q4 | E6: East | F6: Kolkata-01 | G6: Furniture | H6: Wardrobe 3-Door | I6: Amit Singh | J6: 10 | K6: 6700 | L6: 67000 | M6: 41342.99 | N6: 25657.01 | O6: 0.3829 | P6: No
A7: ORD-1006 | B7: 45477 | C7: July | D7: Q3 | E7: Central | F7: Nagpur-01 | G7: Electronics | H7: iPhone 15 | I7: Suresh Kumar | J7: 3 | K7: 62980 | L7: 188940 | M7: 140659.83 | N7: 48280.17 | O7: 0.2555 | P7: No
A8: ORD-1007 | B8: 45486 | C8: July | D8: Q3 | E8: East | F8: Bhubaneswar-01 | G8: Groceries | H8: Atta 10kg | I8: Amit Singh | J8: 9 | K8: 840 | L8: 7560 | M8: 6046.62 | N8: 1513.38 | O8: 0.2002 | P8: No
A9: ORD-1008 | B9: 45328 | C9: February | D9: Q1 | E9: Central | F9: Indore-01 | G9: Clothing | H9: Women's Kurta | I9: Suresh Kumar | J9: 9 | K9: 2580 | L9: 23220 | M9: 11634.33 | N9: 11585.67 | O9: 0.499 | P9: No
A10: ORD-1009 | B10: 45577 | C10: October | D10: Q4 | E10: South | F10: Hyderabad-01 | G10: Groceries | H10: Cooking Oil 5L | I10: Rahul Gupta | J10: 11 | K10: 1680 | L10: 18480 | M10: 15336.25 | N10: 3143.75 | O10: 0.1701 | P10: Yes
A11: ORD-1010 | B11: 45582 | C11: October | D11: Q4 | E11: East | F11: Kolkata-01 | G11: Furniture | H11: Wardrobe 3-Door | I11: Kavya Nair | J11: 5 | K11: 9710 | L11: 48550 | M11: 32787.62 | N11: 15762.38 | O11: 0.3247 | P11: No
A12: ORD-1011 | B12: 45426 | C12: May | D12: Q2 | E12: Central | F12: Bhopal-01 | G12: Sports | H12: Dumbbells Set | I12: Meera Joshi | J12: 5 | K12: 3910 | L12: 19550 | M12: 13666.38 | N12: 5883.62 | O12: 0.301 | P12: No
A13: ORD-1012 | B13: 45316 | C13: January | D13: Q1 | E13: North | F13: Delhi-01 | G13: Clothing | H13: Formal Suit | I13: Priya Patel | J13: 13 | K13: 790 | L13: 10270 | M13: 5550.02 | N13: 4719.98 | O13: 0.4596 | P13: No
... A501: ORD-1500 | B501: 45499 | C501: July | D501: Q3 | E501: North | F501: Delhi-01 | G501: Clothing | H501: Women's Kurta | I501: Priya Patel | J501: 10 | K501: 1910 | L501: 19100 | M501: 10103.07 | N501: 8996.93 | O501: 0.471 | P501: No

Sheet Monthly_Summary
A1: SuperMart Retail — Monthly Performance Summary 2024
A2: Source: Sales_Data Sheet | Data Period: Jan 2024 – Dec 2024 | 500 Transactions
A3: Month | B3: Orders | C3: Units Sold | D3: Revenue (₹) | E3: COGS (₹) | F3: Gross Profit (₹) | G3: Margin % | H3: MoM Growth % | I3: Returns
A4: January | B4: =COUNTIF(Sales_Data!C:C,A4) -> 32 | C4: =SUMIF(Sales_Data!C:C,A4,Sales_Data!J:J) -> 366 | D4: =SUMIF(Sales_Data!C:C,A4,Sales_Data!L:L) -> 6580400 | E4: =SUMIF(Sales_Data!C:C,A4,Sales_Data!M:M) -> 4805969.2 | F4: =D4-E4 -> 1774430.8 | G4: =IFERROR(F4/D4,0) -> 0.26965393 | H4: - | I4: =COUNTIFS(Sales_Data!C:C,A4,Sales_Data!P:P,"Yes") -> 2
A5: February | B5: =COUNTIF(Sales_Data!C:C,A5) -> 54 | C5: =SUMIF(Sales_Data!C:C,A5,Sales_Data!J:J) -> 565 | D5: =SUMIF(Sales_Data!C:C,A5,Sales_Data!L:L) -> 8919190 | E5: =SUMIF(Sales_Data!C:C,A5,Sales_Data!M:M) -> 6377812.3 | F5: =D5-E5 -> 2541377.7 | G5: =IFERROR(F5/D5,0) -> 0.28493369 | H5: =IFERROR((D5-D4)/D4,0) -> 0.3554176 | I5: =COUNTIFS(Sales_Data!C:C,A5,Sales_Data!P:P,"Yes") -> 5
A6: March | B6: =COUNTIF(Sales_Data!C:C,A6) -> 38 | C6: =SUMIF(Sales_Data!C:C,A6,Sales_Data!J:J) -> 466 | D6: =SUMIF(Sales_Data!C:C,A6,Sales_Data!L:L) -> 5759980 | E6: =SUMIF(Sales_Data!C:C,A6,Sales_Data!M:M) -> 4022515.5 | F6: =D6-E6 -> 1737464.5 | G6: =IFERROR(F6/D6,0) -> 0.30164418 | H6: =IFERROR((D6-D5)/D5,0) -> -0.35420369 | I6: =COUNTIFS(Sales_Data!C:C,A6,Sales_Data!P:P,"Yes") -> 2
A7: April | B7: =COUNTIF(Sales_Data!C:C,A7) -> 33 | C7: =SUMIF(Sales_Data!C:C,A7,Sales_Data!J:J) -> 367 | D7: =SUMIF(Sales_Data!C:C,A7,Sales_Data!L:L) -> 5818470 | E7: =SUMIF(Sales_Data!C:C,A7,Sales_Data!M:M) -> 4340429 | F7: =D7-E7 -> 1478041 | G7: =IFERROR(F7/D7,0) -> 0.25402571 | H7: =IFERROR((D7-D6)/D6,0) -> 0.010154549 | I7: =COUNTIFS(Sales_Data!C:C,A7,Sales_Data!P:P,"Yes") -> 1
A8: May | B8: =COUNTIF(Sales_Data!C:C,A8) -> 48 | C8: =SUMIF(Sales_Data!C:C,A8,Sales_Data!J:J) -> 497 | D8: =SUMIF(Sales_Data!C:C,A8,Sales_Data!L:L) -> 9601970 | E8: =SUMIF(Sales_Data!C:C,A8,Sales_Data!M:M) -> 6825995.6 | F8: =D8-E8 -> 2775974.4 | G8: =IFERROR(F8/D8,0) -> 0.28910467 | H8: =IFERROR((D8-D7)/D7,0) -> 0.65025685 | I8: =COUNTIFS(Sales_Data!C:C,A8,Sales_Data!P:P,"Yes") -> 3
A9: June | B9: =COUNTIF(Sales_Data!C:C,A9) -> 37 | C9: =SUMIF(Sales_Data!C:C,A9,Sales_Data!J:J) -> 382 | D9: =SUMIF(Sales_Data!C:C,A9,Sales_Data!L:L) -> 6869620 | E9: =SUMIF(Sales_Data!C:C,A9,Sales_Data!M:M) -> 5081412.2 | F9: =D9-E9 -> 1788207.8 | G9: =IFERROR(F9/D9,0) -> 0.26030665 | H9: =IFERROR((D9-D8)/D8,0) -> -0.2845614 | I9: =COUNTIFS(Sales_Data!C:C,A9,Sales_Data!P:P,"Yes") -> 0
A10: July | B10: =COUNTIF(Sales_Data!C:C,A10) -> 48 | C10: =SUMIF(Sales_Data!C:C,A10,Sales_Data!J:J) -> 502 | D10: =SUMIF(Sales_Data!C:C,A10,Sales_Data!L:L) -> 6966520 | E10: =SUMIF(Sales_Data!C:C,A10,Sales_Data!M:M) -> 4971156.9 | F10: =D10-E10 -> 1995363.1 | G10: =IFERROR(F10/D10,0) -> 0.28642179 | H10: =IFERROR((D10-D9)/D9,0) -> 0.014105584 | I10: =COUNTIFS(Sales_Data!C:C,A10,Sales_Data!P:P,"Yes") -> 0
A11: August | B11: =COUNTIF(Sales_Data!C:C,A11) -> 34 | C11: =SUMIF(Sales_Data!C:C,A11,Sales_Data!J:J) -> 362 | D11: =SUMIF(Sales_Data!C:C,A11,Sales_Data!L:L) -> 8013470 | E11: =SUMIF(Sales_Data!C:C,A11,Sales_Data!M:M) -> 5942332.5 | F11: =D11-E11 -> 2071137.5 | G11: =IFERROR(F11/D11,0) -> 0.25845701 | H11: =IFERROR((D11-D10)/D10,0) -> 0.15028307 | I11: =COUNTIFS(Sales_Data!C:C,A11,Sales_Data!P:P,"Yes") -> 1
A12: September | B12: =COUNTIF(Sales_Data!C:C,A12) -> 27 | C12: =SUMIF(Sales_Data!C:C,A12,Sales_Data!J:J) -> 268 | D12: =SUMIF(Sales_Data!C:C,A12,Sales_Data!L:L) -> 5430530 | E12: =SUMIF(Sales_Data!C:C,A12,Sales_Data!M:M) -> 4046659.4 | F12: =D12-E12 -> 1383870.6 | G12: =IFERROR(F12/D12,0) -> 0.25483159 | H12: =IFERROR((D12-D11)/D11,0) -> -0.32232479 | I12: =COUNTIFS(Sales_Data!C:C,A12,Sales_Data!P:P,"Yes") -> 1
A13: October | B13: =COUNTIF(Sales_Data!C:C,A13) -> 59 | C13: =SUMIF(Sales_Data!C:C,A13,Sales_Data!J:J) -> 608 | D13: =SUMIF(Sales_Data!C:C,A13,Sales_Data!L:L) -> 8198170 | E13: =SUMIF(Sales_Data!C:C,A13,Sales_Data!M:M) -> 5816088.4 | F13: =D13-E13 -> 2382081.6 | G13: =IFERROR(F13/D13,0) -> 0.2905626 | H13: =IFERROR((D13-D12)/D12,0) -> 0.50964455 | I13: =COUNTIFS(Sales_Data!C:C,A13,Sales_Data!P:P,"Yes") -> 3
A14: November | B14: =COUNTIF(Sales_Data!C:C,A14) -> 49 | C14: =SUMIF(Sales_Data!C:C,A14,Sales_Data!J:J) -> 542 | D14: =SUMIF(Sales_Data!C:C,A14,Sales_Data!L:L) -> 10027570 | E14: =SUMIF(Sales_Data!C:C,A14,Sales_Data!M:M) -> 7428088.5 | F14: =D14-E14 -> 2599481.5 | G14: =IFERROR(F14/D14,0) -> 0.25923345 | H14: =IFERROR((D14-D13)/D13,0) -> 0.22314736 | I14: =COUNTIFS(Sales_Data!C:C,A14,Sales_Data!P:P,"Yes") -> 0
A15: December | B15: =COUNTIF(Sales_Data!C:C,A15) -> 41 | C15: =SUMIF(Sales_Data!C:C,A15,Sales_Data!J:J) -> 429 | D15: =SUMIF(Sales_Data!C:C,A15,Sales_Data!L:L) -> 5992600 | E15: =SUMIF(Sales_Data!C:C,A15,Sales_Data!M:M) -> 4061243.8 | F15: =D15-E15 -> 1931356.2 | G15: =IFERROR(F15/D15,0) -> 0.3222902 | H15: =IFERROR((D15-D14)/D14,0) -> -0.40238762 | I15: =COUNTIFS(Sales_Data!C:C,A15,Sales_Data!P:P,"Yes") -> 2
A16: TOTAL / AVG | B16: =SUM(B4:B15) -> 500 | C16: =SUM(C4:C15) -> 5354 | D16: =SUM(D4:D15) -> 88178490 | E16: =SUM(E4:E15) -> 63719703 | F16: =SUM(F4:F15) -> 24458787 | G16: =AVERAGE(G4:G15) -> 0.27762212 | H16: — | I16: =SUM(I4:I15) -> 20

Sheet Regional_Analysis
A1: SuperMart Retail — Regional Performance Analysis 2024
A2: Region | B2: Orders | C2: Units Sold | D2: Revenue (₹) | E2: COGS (₹) | F2: Gross Profit (₹) | G2: Margin % | H2: Revenue Share % | I2: Rank | J2: Returns
A3: North | B3: =COUNTIF(Sales_Data!E:E,A3) -> 94 | C3: =SUMIF(Sales_Data!E:E,A3,Sales_Data!J:J) -> 986 | D3: =SUMIF(Sales_Data!E:E,A3,Sales_Data!L:L) -> 16101730 | E3: =SUMIF(Sales_Data!E:E,A3,Sales_Data!M:M) -> 11537337 | F3: =D3-E3 -> 4564393.2 | G3: =IFERROR(F3/D3,0) -> 0.28347222 | H3: =IFERROR(D3/SUM($D$3:$D$7),0) -> 0.18260383 | I3: =RANK(D3,$D$3:$D$7,0) -> 4 | J3: =COUNTIFS(Sales_Data!E:E,A3,Sales_Data!P:P,"Yes") -> 5
A4: South | B4: =COUNTIF(Sales_Data!E:E,A4) -> 114 | C4: =SUMIF(Sales_Data!E:E,A4,Sales_Data!J:J) -> 1135 | D4: =SUMIF(Sales_Data!E:E,A4,Sales_Data!L:L) -> 20329410 | E4: =SUMIF(Sales_Data!E:E,A4,Sales_Data!M:M) -> 14988476 | F4: =D4-E4 -> 5340934.2 | G4: =IFERROR(F4/D4,0) -> 0.26271959 | H4: =IFERROR(D4/SUM($D$3:$D$7),0) -> 0.2305484 | I4: =RANK(D4,$D$3:$D$7,0) -> 1 | J4: =COUNTIFS(Sales_Data!E:E,A4,Sales_Data!P:P,"Yes") -> 7
A5: East | B5: =COUNTIF(Sales_Data!E:E,A5) -> 92 | C5: =SUMIF(Sales_Data!E:E,A5,Sales_Data!J:J) -> 1034 | D5: =SUMIF(Sales_Data!E:E,A5,Sales_Data!L:L) -> 18011490 | E5: =SUMIF(Sales_Data!E:E,A5,Sales_Data!M:M) -> 13085106 | F5: =D5-E5 -> 4926384.1 | G5: =IFERROR(F5/D5,0) -> 0.27351341 | H5: =IFERROR(D5/SUM($D$3:$D$7),0) -> 0.20426172 | I5: =RANK(D5,$D$3:$D$7,0) -> 3 | J5: =COUNTIFS(Sales_Data!E:E,A5,Sales_Data!P:P,"Yes") -> 3
A6: West | B6: =COUNTIF(Sales_Data!E:E,A6) -> 89 | C6: =SUMIF(Sales_Data!E:E,A6,Sales_Data!J:J) -> 1025 | D6: =SUMIF(Sales_Data!E:E,A6,Sales_Data!L:L) -> 13755920 | E6: =SUMIF(Sales_Data!E:E,A6,Sales_Data!M:M) -> 9712642.9 | F6: =D6-E6 -> 4043277.1 | G6: =IFERROR(F6/D6,0) -> 0.29392997 | H6: =IFERROR(D6/SUM($D$3:$D$7),0) -> 0.15600086 | I6: =RANK(D6,$D$3:$D$7,0) -> 5 | J6: =COUNTIFS(Sales_Data!E:E,A6,Sales_Data!P:P,"Yes") -> 2
A7: Central | B7: =COUNTIF(Sales_Data!E:E,A7) -> 111 | C7: =SUMIF(Sales_Data!E:E,A7,Sales_Data!J:J) -> 1174 | D7: =SUMIF(Sales_Data!E:E,A7,Sales_Data!L:L) -> 19979940 | E7: =SUMIF(Sales_Data!E:E,A7,Sales_Data!M:M) -> 14396142 | F7: =D7-E7 -> 5583798.1 | G7: =IFERROR(F7/D7,0) -> 0.27947021 | H7: =IFERROR(D7/SUM($D$3:$D$7),0) -> 0.22658519 | I7: =RANK(D7,$D$3:$D$7,0) -> 2 | J7: =COUNTIFS(Sales_Data!E:E,A7,Sales_Data!P:P,"Yes") -> 3
A8: GRAND TOTAL | B8: =SUM(B3:B7) -> 500 | C8: =SUM(C3:C7) -> 5354 | D8: =SUM(D3:D7) -> 88178490 | E8: =SUM(E3:E7) -> 63719703 | F8: =SUM(F3:F7) -> 24458787 | G8: =AVERAGE(G3:G7) -> 0.27862108 | H8: =SUM(H3:H7) -> 1 | J8: =SUM(J3:J7) -> 20
A10: Category Performance
A11: Category | B11: Orders | C11: Units Sold | D11: Revenue (₹) | E11: Gross Profit (₹) | F11: Margin % | G11: Return Rate %
A12: Electronics | B12: =COUNTIF(Sales_Data!G:G,A12) -> 91 | C12: =SUMIF(Sales_Data!G:G,A12,Sales_Data!J:J) -> 1033 | D12: =SUMIF(Sales_Data!G:G,A12,Sales_Data!L:L) -> 46970140 | E12: =SUMIF(Sales_Data!G:G,A12,Sales_Data!N:N) -> 10494358 | F12: =IFERROR(E12/D12,0) -> 0.22342615 | G12: =IFERROR(COUNTIFS(Sales_Data!G:G,A12,Sales_Data!P:P,"Yes")/B12,0) -> 0.065934066
A13: Clothing | B13: =COUNTIF(Sales_Data!G:G,A13) -> 86 | C13: =SUMIF(Sales_Data!G:G,A13,Sales_Data!J:J) -> 969 | D13: =SUMIF(Sales_Data!G:G,A13,Sales_Data!L:L) -> 2941370 | E13: =SUMIF(Sales_Data!G:G,A13,Sales_Data!N:N) -> 1319147.8 | F13: =IFERROR(E13/D13,0) -> 0.44848073 | G13: =IFERROR(COUNTIFS(Sales_Data!G:G,A13,Sales_Data!P:P,"Yes")/B13,0) -> 0.023255814
A14: Groceries | B14: =COUNTIF(Sales_Data!G:G,A14) -> 97 | C14: =SUMIF(Sales_Data!G:G,A14,Sales_Data!J:J) -> 1050 | D14: =SUMIF(Sales_Data!G:G,A14,Sales_Data!L:L) -> 1224330 | E14: =SUMIF(Sales_Data!G:G,A14,Sales_Data!N:N) -> 228130.25 | F14: =IFERROR(E14/D14,0) -> 0.18633069 | G14: =IFERROR(COUNTIFS(Sales_Data!G:G,A14,Sales_Data!P:P,"Yes")/B14,0) -> 0.041237113
A15: Furniture | B15: =COUNTIF(Sales_Data!G:G,A15) -> 119 | C15: =SUMIF(Sales_Data!G:G,A15,Sales_Data!J:J) -> 1218 | D15: =SUMIF(Sales_Data!G:G,A15,Sales_Data!L:L) -> 28889360 | E15: =SUMIF(Sales_Data!G:G,A15,Sales_Data!N:N) -> 10003875 | F15: =IFERROR(E15/D15,0) -> 0.34628232 | G15: =IFERROR(COUNTIFS(Sales_Data!G:G,A15,Sales_Data!P:P,"Yes")/B15,0) -> 0.042016807
A16: Sports | B16: =COUNTIF(Sales_Data!G:G,A16) -> 107 | C16: =SUMIF(Sales_Data!G:G,A16,Sales_Data!J:J) -> 1084 | D16: =SUMIF(Sales_Data!G:G,A16,Sales_Data!L:L) -> 8153290 | E16: =SUMIF(Sales_Data!G:G,A16,Sales_Data!N:N) -> 2413276.4 | F16: =IFERROR(E16/D16,0) -> 0.29598805 | G16: =IFERROR(COUNTIFS(Sales_Data!G:G,A16,Sales_Data!P:P,"Yes")/B16,0) -> 0.028037383

Sheet Salesperson_Scorecard
A1: SuperMart Retail — Salesperson Performance Scorecard 2024
A2: Annual Targets: Revenue ₹40,00,000 per Rep | Margin Target: 30% | Max Returns: 5%
A3: Salesperson | B3: Region | C3: Orders | D3: Units | E3: Revenue (₹) | F3: Gross Profit (₹) | G3: Margin % | H3: vs Target % | I3: Returns | J3: Rating
A4: Arjun Sharma | B4: North | C4: =COUNTIF(Sales_Data!I:I,A4) -> 53 | D4: =SUMIF(Sales_Data!I:I,A4,Sales_Data!J:J) -> 584 | E4: =SUMIF(Sales_Data!I:I,A4,Sales_Data!L:L) -> 8979690 | F4: =SUMIF(Sales_Data!I:I,A4,Sales_Data!N:N) -> 2474067.9 | G4: =IFERROR(F4/E4,0) -> 0.27551819 | H4: =IFERROR((E4-4000000)/4000000,0) -> 1.2449225 | I4: =COUNTIFS(Sales_Data!I:I,A4,Sales_Data!P:P,"Yes") -> 4 | J4: =IF(E4>=4000000*1.1,"⭐ Excellent",IF(E4>=4000000,"✅ On Target",IF(E4>=4000000*0.85,"⚠️ Near Target","❌ Below Target"))) -> ⭐ Excellent
A5: Priya Patel | B5: North | C5: =COUNTIF(Sales_Data!I:I,A5) -> 41 | D5: =SUMIF(Sales_Data!I:I,A5,Sales_Data!J:J) -> 402 | E5: =SUMIF(Sales_Data!I:I,A5,Sales_Data!L:L) -> 7122040 | F5: =SUMIF(Sales_Data!I:I,A5,Sales_Data!N:N) -> 2090325.3 | G5: =IFERROR(F5/E5,0) -> 0.29350091 | H5: =IFERROR((E5-4000000)/4000000,0) -> 0.78051 | I5: =COUNTIFS(Sales_Data!I:I,A5,Sales_Data!P:P,"Yes") -> 1 | J5: =IF(E5>=4000000*1.1,"⭐ Excellent",IF(E5>=4000000,"✅ On Target",IF(E5>=4000000*0.85,"⚠️ Near Target","❌ Below Target"))) -> ⭐ Excellent
A6: Rahul Gupta | B6: South | C6: =COUNTIF(Sales_Data!I:I,A6) -> 59 | D6: =SUMIF(Sales_Data!I:I,A6,Sales_Data!J:J) -> 601 | E6: =SUMIF(Sales_Data!I:I,A6,Sales_Data!L:L) -> 13650710 | F6: =SUMIF(Sales_Data!I:I,A6,Sales_Data!N:N) -> 3403022.4 | G6: =IFERROR(F6/E6,0) -> 0.2492927 | H6: =IFERROR((E6-4000000)/4000000,0) -> 2.4126775 | I6: =COUNTIFS(Sales_Data!I:I,A6,Sales_Data!P:P,"Yes") -> 4 | J6: =IF(E6>=4000000*1.1,"⭐ Excellent",IF(E6>=4000000,"✅ On Target",IF(E6>=4000000*0.85,"⚠️ Near Target","❌ Below Target"))) -> ⭐ Excellent
A7: Sneha Reddy | B7: South | C7: =COUNTIF(Sales_Data!I:I,A7) -> 55 | D7: =SUMIF(Sales_Data!I:I,A7,Sales_Data!J:J) -> 534 | E7: =SUMIF(Sales_Data!I:I,A7,Sales_Data!L:L) -> 6678700 | F7: =SUMIF(Sales_Data!I:I,A7,Sales_Data!N:N) -> 1937911.8 | G7: =IFERROR(F7/E7,0) -> 0.29016303 | H7: =IFERROR((E7-4000000)/4000000,0) -> 0.669675 | I7: =COUNTIFS(Sales_Data!I:I,A7,Sales_Data!P:P,"Yes") -> 3 | J7: =IF(E7>=4000000*1.1,"⭐ Excellent",IF(E7>=4000000,"✅ On Target",IF(E7>=4000000*0.85,"⚠️ Near Target","❌ Below Target"))) -> ⭐ Excellent
A8: Amit Singh | B8: East | C8: =COUNTIF(Sales_Data!I:I,A8) -> 49 | D8: =SUMIF(Sales_Data!I:I,A8,Sales_Data!J:J) -> 573 | E8: =SUMIF(Sales_Data!I:I,A8,Sales_Data!L:L) -> 9674340 | F8: =SUMIF(Sales_Data!I:I,A8,Sales_Data!N:N) -> 2651500.9 | G8: =IFERROR(F8/E8,0) -> 0.27407564 | H8: =IFERROR((E8-4000000)/4000000,0) -> 1.418585 | I8: =COUNTIFS(Sales_Data!I:I,A8,Sales_Data!P:P,"Yes") -> 2 | J8: =IF(E8>=4000000*1.1,"⭐ Excellent",IF(E8>=4000000,"✅ On Target",IF(E8>=4000000*0.85,"⚠️ Near Target","❌ Below Target"))) -> ⭐ Excellent
A9: Kavya Nair | B9: East | C9: =COUNTIF(Sales_Data!I:I,A9) -> 43 | D9: =SUMIF(Sales_Data!I:I,A9,Sales_Data!J:J) -> 461 | E9: =SUMIF(Sales_Data!I:I,A9,Sales_Data!L:L) -> 8337150 | F9: =SUMIF(Sales_Data!I:I,A9,Sales_Data!N:N) -> 2274883.2 | G9: =IFERROR(F9/E9,0) -> 0.27286102 | H9: =IFERROR((E9-4000000)/4000000,0) -> 1.0842875 | I9: =COUNTIFS(Sales_Data!I:I,A9,Sales_Data!P:P,"Yes") -> 1 | J9: =IF(E9>=4000000*1.1,"⭐ Excellent",IF(E9>=4000000,"✅ On Target",IF(E9>=4000000*0.85,"⚠️ Near Target","❌ Below Target"))) -> ⭐ Excellent
A10: Rohan Mehta | B10: West | C10: =COUNTIF(Sales_Data!I:I,A10) -> 42 | D10: =SUMIF(Sales_Data!I:I,A10,Sales_Data!J:J) -> 534 | E10: =SUMIF(Sales_Data!I:I,A10,Sales_Data!L:L) -> 6920960 | F10: =SUMIF(Sales_Data!I:I,A10,Sales_Data!N:N) -> 1912589.8 | G10: =IFERROR(F10/E10,0) -> 0.27634747 | H10: =IFERROR((E10-4000000)/4000000,0) -> 0.73024 | I10: =COUNTIFS(Sales_Data!I:I,A10,Sales_Data!P:P,"Yes") -> 0 | J10: =IF(E10>=4000000*1.1,"⭐ Excellent",IF(E10>=4000000,"✅ On Target",IF(E10>=4000000*0.85,"⚠️ Near Target","❌ Below Target"))) -> ⭐ Excellent
A11: Divya Iyer | B11: West | C11: =COUNTIF(Sales_Data!I:I,A11) -> 47 | D11: =SUMIF(Sales_Data!I:I,A11,Sales_Data!J:J) -> 491 | E11: =SUMIF(Sales_Data!I:I,A11,Sales_Data!L:L) -> 6834960 | F11: =SUMIF(Sales_Data!I:I,A11,Sales_Data!N:N) -> 2130687.3 | G11: =IFERROR(F11/E11,0) -> 0.31173369 | H11: =IFERROR((E11-4000000)/4000000,0) -> 0.70874 | I11: =COUNTIFS(Sales_Data!I:I,A11,Sales_Data!P:P,"Yes") -> 2 | J11: =IF(E11>=4000000*1.1,"⭐ Excellent",IF(E11>=4000000,"✅ On Target",IF(E11>=4000000*0.85,"⚠️ Near Target","❌ Below Target"))) -> ⭐ Excellent
A12: Suresh Kumar | B12: Central | C12: =COUNTIF(Sales_Data!I:I,A12) -> 60 | D12: =SUMIF(Sales_Data!I:I,A12,Sales_Data!J:J) -> 639 | E12: =SUMIF(Sales_Data!I:I,A12,Sales_Data!L:L) -> 11511390 | F12: =SUMIF(Sales_Data!I:I,A12,Sales_Data!N:N) -> 3252511.2 | G12: =IFERROR(F12/E12,0) -> 0.28254722 | H12: =IFERROR((E12-4000000)/4000000,0) -> 1.8778475 | I12: =COUNTIFS(Sales_Data!I:I,A12,Sales_Data!P:P,"Yes") -> 1 | J12: =IF(E12>=4000000*1.1,"⭐ Excellent",IF(E12>=4000000,"✅ On Target",IF(E12>=4000000*0.85,"⚠️ Near Target","❌ Below Target"))) -> ⭐ Excellent
A13: Meera Joshi | B13: Central | C13: =COUNTIF(Sales_Data!I:I,A13) -> 51 | D13: =SUMIF(Sales_Data!I:I,A13,Sales_Data!J:J) -> 535 | E13: =SUMIF(Sales_Data!I:I,A13,Sales_Data!L:L) -> 8468550 | F13: =SUMIF(Sales_Data!I:I,A13,Sales_Data!N:N) -> 2331286.9 | G13: =IFERROR(F13/E13,0) -> 0.27528761 | H13: =IFERROR((E13-4000000)/4000000,0) -> 1.1171375 | I13: =COUNTIFS(Sales_Data!I:I,A13,Sales_Data!P:P,"Yes") -> 2 | J13: =IF(E13>=4000000*1.1,"⭐ Excellent",IF(E13>=4000000,"✅ On Target",IF(E13>=4000000*0.85,"⚠️ Near Target","❌ Below Target"))) -> ⭐ Excellent
